<?xml version="1.0"?>
<!-- A minimal differential-drive robot with a forward 180-degree 2D lidar, for the Kirra
     Gazebo demo. The gazebo_ros_diff_drive plugin subscribes to /cmd_vel (the KIRRA-enforced
     output of the cmd_vel_interceptor) and the gazebo_ros_ray_sensor plugin publishes /scan
     (consumed by the perception_governor -> Taj). Plain URDF (no xacro) so it is directly
     XML-valid and needs no expansion step. -->
<robot name="kirra_bot">

  <!-- Chassis -->
  <link name="base_link">
    <inertial>
      <mass value="3.0"/>
      <inertia ixx="0.03" ixy="0" ixz="0" iyy="0.03" iyz="0" izz="0.05"/>
    </inertial>
    <collision>
      <geometry><box size="0.3 0.3 0.12"/></geometry>
    </collision>
    <visual>
      <geometry><box size="0.3 0.3 0.12"/></geometry>
      <material name="body"><color rgba="0.1 0.4 0.7 1"/></material>
    </visual>
  </link>

  <!-- Left wheel -->
  <link name="left_wheel">
    <inertial>
      <mass value="0.2"/>
      <inertia ixx="0.0005" ixy="0" ixz="0" iyy="0.0005" iyz="0" izz="0.0008"/>
    </inertial>
    <collision>
      <origin rpy="1.5708 0 0"/>
      <geometry><cylinder radius="0.05" length="0.04"/></geometry>
    </collision>
    <visual>
      <origin rpy="1.5708 0 0"/>
      <geometry><cylinder radius="0.05" length="0.04"/></geometry>
      <material name="wheel"><color rgba="0.1 0.1 0.1 1"/></material>
    </visual>
  </link>
  <joint name="left_wheel_joint" type="continuous">
    <parent link="base_link"/>
    <child link="left_wheel"/>
    <origin xyz="0 0.17 -0.04"/>
    <axis xyz="0 1 0"/>
  </joint>

  <!-- Right wheel -->
  <link name="right_wheel">
    <inertial>
      <mass value="0.2"/>
      <inertia ixx="0.0005" ixy="0" ixz="0" iyy="0.0005" iyz="0" izz="0.0008"/>
    </inertial>
    <collision>
      <origin rpy="1.5708 0 0"/>
      <geometry><cylinder radius="0.05" length="0.04"/></geometry>
    </collision>
    <visual>
      <origin rpy="1.5708 0 0"/>
      <geometry><cylinder radius="0.05" length="0.04"/></geometry>
      <material name="wheel"><color rgba="0.1 0.1 0.1 1"/></material>
    </visual>
  </link>
  <joint name="right_wheel_joint" type="continuous">
    <parent link="base_link"/>
    <child link="right_wheel"/>
    <origin xyz="0 -0.17 -0.04"/>
    <axis xyz="0 1 0"/>
  </joint>

  <!-- Front caster (a low-friction sphere keeps the chassis level) -->
  <link name="caster">
    <inertial>
      <mass value="0.05"/>
      <inertia ixx="0.0001" ixy="0" ixz="0" iyy="0.0001" iyz="0" izz="0.0001"/>
    </inertial>
    <collision><geometry><sphere radius="0.03"/></geometry></collision>
    <visual><geometry><sphere radius="0.03"/></geometry></visual>
  </link>
  <joint name="caster_joint" type="fixed">
    <parent link="base_link"/>
    <child link="caster"/>
    <origin xyz="0.12 0 -0.07"/>
  </joint>

  <!-- Lidar mount -->
  <link name="lidar_link">
    <inertial>
      <mass value="0.1"/>
      <inertia ixx="0.0001" ixy="0" ixz="0" iyy="0.0001" iyz="0" izz="0.0001"/>
    </inertial>
    <visual>
      <geometry><cylinder radius="0.03" length="0.04"/></geometry>
      <material name="lidar"><color rgba="0.2 0.2 0.2 1"/></material>
    </visual>
  </link>
  <joint name="lidar_joint" type="fixed">
    <parent link="base_link"/>
    <child link="lidar_link"/>
    <origin xyz="0.1 0 0.09"/>
  </joint>

  <!-- Low-friction caster so the diff drive turns cleanly -->
  <gazebo reference="caster">
    <mu1>0.0</mu1>
    <mu2>0.0</mu2>
  </gazebo>

  <!-- Differential drive: subscribes /cmd_vel (the KIRRA-enforced safe command), publishes odom + tf -->
  <gazebo>
    <plugin name="diff_drive" filename="libgazebo_ros_diff_drive.so">
      <ros><namespace>/</namespace></ros>
      <left_joint>left_wheel_joint</left_joint>
      <right_joint>right_wheel_joint</right_joint>
      <wheel_separation>0.34</wheel_separation>
      <wheel_diameter>0.1</wheel_diameter>
      <max_wheel_torque>10.0</max_wheel_torque>
      <max_wheel_acceleration>2.0</max_wheel_acceleration>
      <command_topic>cmd_vel</command_topic>
      <publish_odom>true</publish_odom>
      <publish_odom_tf>true</publish_odom_tf>
      <publish_wheel_tf>true</publish_wheel_tf>
      <odometry_topic>odom</odometry_topic>
      <odometry_frame>odom</odometry_frame>
      <robot_base_frame>base_link</robot_base_frame>
    </plugin>
  </gazebo>

  <!-- Forward 180-degree 2D lidar: publishes /scan (sensor_msgs/LaserScan), the same forward
       cone Taj's corridor is derived from (matches the taj_service -pi/2..+pi/2 expectation). -->
  <gazebo reference="lidar_link">
    <sensor name="lidar" type="ray">
      <pose>0 0 0 0 0 0</pose>
      <always_on>true</always_on>
      <visualize>true</visualize>
      <update_rate>10</update_rate>
      <ray>
        <scan>
          <horizontal>
            <samples>181</samples>
            <resolution>1</resolution>
            <min_angle>-1.5708</min_angle>
            <max_angle>1.5708</max_angle>
          </horizontal>
        </scan>
        <range>
          <min>0.12</min>
          <max>8.0</max>
          <resolution>0.01</resolution>
        </range>
      </ray>
      <plugin name="lidar_plugin" filename="libgazebo_ros_ray_sensor.so">
        <ros>
          <namespace>/</namespace>
          <remapping>~/out:=scan</remapping>
        </ros>
        <output_type>sensor_msgs/LaserScan</output_type>
        <frame_name>lidar_link</frame_name>
      </plugin>
    </sensor>
  </gazebo>

</robot>
